Workbook

Sheet Healthcare_LifeSciences_Data
A1: Patient ID | B1: Age | C1: Department | D1: Admission Date | E1: Month | F1: Discharge Date | G1: Stay Duration (days) | H1: Disease/Condition | I1: Satisfaction Score | J1: Doctor | K1: Treatment Cost | L1: Medication | M1: Has Insurance | N1: Case Type | O1: Appointment Date | P1: Consultation Date | Q1: Test Type | R1: Test Result | S1: Shift | T1: Staff Hours Worked | U1: Staff Available Hours | V1: Treatment Plan | Y1: Staff Utilization Rate | Z1: Q12.
A2: PAT5000 | B2: 52 | C2: Neurology | D2: 45041 | E2: =TEXT(D2,"MMM") -> Apr | F2: 45082 | G2: 11 | H2: Heart Disease | I2: 3 | J2: Dr. Mehta | K2: 40901 | L2: MedC | M2: No | N2: Routine | O2: 22-04-23 0:00 | P2: 22-04-23 12:00 | Q2: X-Ray | R2: Accepted | S2: Afternoon | T2: 9 | U2: 12 | V2: Plan B | X2: =(P2-O2)*24 -> #VALUE! | Y2: =(T2/U2*100) -> 75
A3: PAT5001 | B3: 15 | C3: ICU | D3: 44952 | E3: =TEXT(D3,"MMM") -> Jan | F3: 44959 | G3: 7 | H3: Fracture | I3: 2 | J3: Dr. Sharma | K3: 49380 | L3: MedE | M3: No | N3: Routine | O3: 22-01-23 0:00 | P3: 22-01-23 21:00 | Q3: Blood Test | R3: Rejected | S3: Afternoon | T3: 9 | U3: 10 | V3: Plan B | X3: =(P3-O3)*24 -> #VALUE! | Y3: =(T3/U3*100) -> 90
A4: PAT5002 | B4: 72 | C4: Neurology | D4: 45179 | E4: =TEXT(D4,"MMM") -> Sep | F4: 45240 | G4: 2 | H4: Hypertension | I4: 5 | J4: Dr. Mehta | K4: 25493 | L4: MedC | M4: No | N4: Emergency | O4: 45179 | P4: 45179.083 | Q4: CT Scan | R4: Rejected | S4: Morning | T4: 10 | U4: 10 | V4: Plan B | Y4: =(T4/U4*100) -> 100
A5: PAT5003 | B5: 61 | C5: General Medicine | D5: 45147 | E5: =TEXT(D5,"MMM") -> Aug | F5: 45239 | G5: 3 | H5: Fracture | I5: 3 | J5: Dr. Gupta | K5: 23595 | L5: MedC | M5: No | N5: Routine | O5: 45025 | P5: 45025.583 | Q5: CT Scan | R5: Accepted | S5: Night | T5: 7 | U5: 12 | V5: Plan C | Y5: =(T5/U5*100) -> 58.333333
A6: PAT5004 | B6: 21 | C6: Emergency | D6: 45155 | E6: =TEXT(D6,"MMM") -> Aug | F6: 18-08-23 0:00 | G6: 1 | H6: Diabetes | I6: 1 | J6: Dr. Gupta | K6: 26923 | L6: MedE | M6: No | N6: Emergency | O6: 16-08-23 0:00 | P6: 17-08-23 14:00 | Q6: CT Scan | R6: Accepted | S6: Night | T6: 5 | U6: 10 | V6: Plan B | Y6: =(T6/U6*100) -> 50
A7: PAT5005 | B7: 83 | C7: Cardiology | D7: 45161 | E7: =TEXT(D7,"MMM") -> Aug | F7: 24-05-23 0:00 | G7: 1 | H7: Diabetes | I7: 3 | J7: Dr. Mehta | K7: 14735 | L7: MedA | M7: Yes | N7: Routine | O7: 18-05-23 0:00 | P7: 18-05-23 10:00 | Q7: Ultrasound | R7: Rejected | S7: Morning | T7: 9 | U7: 12 | V7: Plan C | Y7: =(T7/U7*100) -> 75
A8: PAT5006 | B8: 87 | C8: Cardiology | D8: 45031 | E8: =TEXT(D8,"MMM") -> Apr | F8: 20-04-23 0:00 | G8: 5 | H8: Flu | I8: 1 | J8: Dr. Sharma | K8: 39457 | L8: MedC | M8: Yes | N8: Emergency | O8: 45264 | P8: 13-04-23 22:00 | Q8: X-Ray | R8: Accepted | S8: Afternoon | T8: 10 | U8: 8 | V8: Plan B | Y8: =(T8/U8*100) -> 125
A9: PAT5007 | B9: 75 | C9: ICU | D9: 45016 | E9: =TEXT(D9,"MMM") -> Mar | F9: 45142 | G9: 8 | H9: Diabetes | I9: 5 | J9: Dr. Mehta | K9: 47531 | L9: MedC | M9: Yes | N9: Emergency | O9: 29-03-23 0:00 | P9: 30-03-23 2:00 | Q9: Ultrasound | R9: Accepted | S9: Afternoon | T9: 4 | U9: 8 | V9: Plan C | Y9: =(T9/U9*100) -> 50
A10: PAT5008 | B10: 75 | C10: General Medicine | D10: 45359 | E10: =TEXT(D10,"MMM") -> Mar | F10: 45568 | G10: 2 | H10: Fracture | I10: 5 | J10: Dr. Mehta | K10: 12727 | L10: MedD | M10: Yes | N10: Routine | O10: 45446 | P10: 45446.208 | Q10: Ultrasound | R10: Accepted | S10: Night | T10: 9 | U10: 12 | V10: Plan C | Y10: =(T10/U10*100) -> 75
A11: PAT5009 | B11: 88 | C11: Orthopedics | D11: 44959 | E11: =TEXT(D11,"MMM") -> Feb | F11: 45018 | G11: 2 | H11: Migraine | I11: 4 | J11: Dr. Mehta | K11: 12764 | L11: MedE | M11: Yes | N11: Routine | O11: 30-01-23 0:00 | P11: 30-01-23 20:00 | Q11: MRI | R11: Accepted | S11: Night | T11: 6 | U11: 8 | V11: Plan C | Y11: =(T11/U11*100) -> 75
A12: PAT5010 | B12: 24 | C12: General Medicine | D12: 44957 | E12: =TEXT(D12,"MMM") -> Jan | F12: 45018 | G12: 4 | H12: Migraine | I12: 4 | J12: Dr. Rao | K12: 32599 | L12: MedB | M12: No | N12: Routine | O12: 31-01-23 0:00 | P12: 31-01-23 11:00 | Q12: X-Ray | R12: Accepted | S12: Night | T12: 6 | U12: 10 | V12: Plan A | Y12: =(T12/U12*100) -> 60
A13: PAT5011 | B13: 3 | C13: Cardiology | D13: 45022 | E13: =TEXT(D13,"MMM") -> Apr | F13: 21-04-23 0:00 | G13: 15 | H13: Flu | I13: 4 | J13: Dr. Gupta | K13: 5818 | L13: MedA | M13: No | N13: Emergency | O13: 44961 | P13: 44989.542 | Q13: CT Scan | R13: Accepted | S13: Night | T13: 4 | U13: 8 | V13: Plan B | Y13: =(T13/U13*100) -> 50
A14: PAT5012 | B14: 22 | C14: Cardiology | D14: 45150 | E14: =TEXT(D14,"MMM") -> Aug | F14: 21-08-23 0:00 | G14: 9 | H14: Heart Disease | I14: 5 | J14: Dr. Patel | K14: 42289 | L14: MedA | M14: Yes | N14: Routine | O14: 45238 | P14: 45238.667 | Q14: Blood Test | R14: Accepted | S14: Night | T14: 11 | U14: 8 | V14: Plan A | Y14: =(T14/U14*100) -> 137.5
A15: PAT5013 | B15: 53 | C15: Emergency | D15: 45165 | E15: =TEXT(D15,"MMM") -> Aug | F15: 30-08-23 0:00 | G15: 3 | H15: Fracture | I15: 2 | J15: Dr. Patel | K15: 38892 | L15: MedE | M15: Yes | N15: Routine | O15: 23-08-23 0:00 | P15: 24-08-23 13:00 | Q15: CT Scan | R15: Accepted | S15: Afternoon | T15: 7 | U15: 12 | V15: Plan B | Y15: =(T15/U15*100) -> 58.333333
A16: PAT5014 | B16: 2 | C16: General Medicine | D16: 45297 | E16: =TEXT(D16,"MMM") -> Jan | F16: 45510 | G16: 7 | H16: Fracture | I16: 5 | J16: Dr. Rao | K16: 10660 | L16: MedD | M16: No | N16: Routine | O16: 30-05-24 0:00 | P16: 31-05-24 1:00 | Q16: Ultrasound | R16: Accepted | S16: Afternoon | T16: 11 | U16: 10 | V16: Plan B | Y16: =(T16/U16*100) -> 110
A17: PAT5015 | B17: 88 | C17: General Medicine | D17: 44954 | E17: =TEXT(D17,"MMM") -> Jan | F17: 45048 | G17: 8 | H17: Diabetes | I17: 3 | J17: Dr. Mehta | K17: 34521 | L17: MedD | M17: Yes | N17: Emergency | O17: 25-01-23 0:00 | P17: 26-01-23 20:00 | Q17: X-Ray | R17: Accepted | S17: Afternoon | T17: 5 | U17: 8 | V17: Plan A | Y17: =(T17/U17*100) -> 62.5
A18: PAT5016 | B18: 30 | C18: Cardiology | D18: 45130 | E18: =TEXT(D18,"MMM") -> Jul | F18: 29-07-23 0:00 | G18: 6 | H18: Fracture | I18: 5 | J18: Dr. Rao | K18: 43409 | L18: MedE | M18: No | N18: Routine | O18: 21-07-23 0:00 | P18: 22-07-23 11:00 | Q18: X-Ray | R18: Accepted | S18: Afternoon | T18: 11 | U18: 8 | V18: Plan C | Y18: =(T18/U18*100) -> 137.5
A19: PAT5017 | B19: 38 | C19: Orthopedics | D19: 45356 | E19: =TEXT(D19,"MMM") -> Mar | F19: 16-03-24 0:00 | G19: 11 | H19: Hypertension | I19: 5 | J19: Dr. Rao | K19: 39470 | L19: MedD | M19: Yes | N19: Emergency | O19: 29-02-24 0:00 | P19: 29-02-24 22:00 | Q19: X-Ray | R19: Accepted | S19: Morning | T19: 5 | U19: 12 | V19: Plan B | Y19: =(T19/U19*100) -> 41.666667
A20: PAT5018 | B20: 2 | C20: ICU | D20: 45152 | E20: =TEXT(D20,"MMM") -> Aug | F20: 26-08-23 0:00 | G20: 12 | H20: Heart Disease | I20: 1 | J20: Dr. Sharma | K20: 23385 | L20: MedA | M20: No | N20: Routine | O20: 45268 | P20: 13-08-23 1:00 | Q20: MRI | R20: Accepted | S20: Afternoon | T20: 9 | U20: 12 | V20: Plan C | Y20: =(T20/U20*100) -> 75
A21: PAT5019 | B21: 64 | C21: ICU | D21: 45386 | E21: =TEXT(D21,"MMM") -> Apr | F21: 16-04-24 0:00 | G21: 12 | H21: Diabetes | I21: 1 | J21: Dr. Gupta | K21: 28296 | L21: MedA | M21: Yes | N21: Routine | O21: 45355 | P21: 45416 | Q21: CT Scan | R21: Accepted | S21: Morning | T21: 6 | U21: 10 | V21: Plan A | Y21: =(T21/U21*100) -> 60
A22: PAT5020 | B22: 60 | C22: General Medicine | D22: 45211 | E22: =TEXT(D22,"MMM") -> Oct | F22: 21-10-23 0:00 | G22: 9 | H22: Hypertension | I22: 1 | J22: Dr. Patel | K22: 28616 | L22: MedB | M22: No | N22: Routine | O22: 45270 | P22: 45270.375 | Q22: MRI | R22: Accepted | S22: Afternoon | T22: 7 | U22: 8 | V22: Plan C | Y22: =(T22/U22*100) -> 87.5
A23: PAT5021 | B23: 21 | C23: ICU | D23: 44933 | E23: =TEXT(D23,"MMM") -> Jan | F23: 14-01-23 0:00 | G23: 7 | H23: Flu | I23: 5 | J23: Dr. Mehta | K23: 31382 | L23: MedE | M23: Yes | N23: Routine | O23: 45108 | P23: 45139.875 | Q23: Blood Test | R23: Accepted | S23: Night | T23: 7 | U23: 12 | V23: Plan B | Y23: =(T23/U23*100) -> 58.333333
A24: PAT5022 | B24: 33 | C24: Cardiology | D24: 45090 | E24: =TEXT(D24,"MMM") -> Jun | F24: 23-06-23 0:00 | G24: 10 | H24: Migraine | I24: 2 | J24: Dr. Patel | K24: 16139 | L24: MedC | M24: Yes | N24: Routine | O24: 45144 | P24: 45175.958 | Q24: Ultrasound | R24: Accepted | S24: Night | T24: 7 | U24: 12 | V24: Plan B | Y24: =(T24/U24*100) -> 58.333333
A25: PAT5023 | B25: 76 | C25: Cardiology | D25: 45359 | E25: =TEXT(D25,"MMM") -> Mar | F25: 20-03-24 0:00 | G25: 12 | H25: Flu | I25: 3 | J25: Dr. Patel | K25: 37060 | L25: MedC | M25: Yes | N25: Routine | O25: 45476 | P25: 45476.25 | Q25: MRI | R25: Accepted | S25: Night | T25: 9 | U25: 12 | V25: Plan B | Y25: =(T25/U25*100) -> 75
A26: PAT5024 | B26: 58 | C26: General Medicine | D26: 45275 | E26: =TEXT(D26,"MMM") -> Dec | F26: 27-12-23 0:00 | G26: 12 | H26: Migraine | I26: 3 | J26: Dr. Gupta | K26: 27419 | L26: MedB | M26: Yes | N26: Routine | O26: 45272 | P26: 13-12-23 9:00 | Q26: MRI | R26: Accepted | S26: Morning | T26: 5 | U26: 10 | V26: Plan A | Y26: =(T26/U26*100) -> 50
A27: PAT5025 | B27: 22 | C27: General Medicine | D27: 45211 | E27: =TEXT(D27,"MMM") -> Oct | F27: 15-10-23 0:00 | G27: 3 | H27: Flu | I27: 2 | J27: Dr. Patel | K27: 32785 | L27: MedB | M27: No | N27: Routine | O27: 45148 | P27: 45209 | Q27: Ultrasound | R27: Accepted | S27: Afternoon | T27: 7 | U27: 12 | V27: Plan B | Y27: =(T27/U27*100) -> 58.333333
A28: PAT5026 | B28: 89 | C28: Emergency | D28: 45086 | E28: =TEXT(D28,"MMM") -> Jun | F28: 24-06-23 0:00 | G28: 15 | H28: Fracture | I28: 2 | J28: Dr. Patel | K28: 20702 | L28: MedD | M28: No | N28: Routine | O28: 45083 | P28: 45083.958 | Q28: X-Ray | R28: Accepted | S28: Afternoon | T28: 9 | U28: 10 | V28: Plan A | Y28: =(T28/U28*100) -> 90
A29: PAT5027 | B29: 49 | C29: General Medicine | D29: 45147 | E29: =TEXT(D29,"MMM") -> Aug | F29: 16-08-23 0:00 | G29: 7 | H29: Hypertension | I29: 3 | J29: Dr. Rao | K29: 34217 | L29: MedB | M29: Yes | N29: Routine | O29: 45054 | P29: 45054.167 | Q29: Ultrasound | R29: Accepted | S29: Morning | T29: 9 | U29: 10 | V29: Plan C | Y29: =(T29/U29*100) -> 90
A30: PAT5028 | B30: 59 | C30: Orthopedics | D30: 45271 | E30: =TEXT(D30,"MMM") -> Dec | F30: 22-12-23 0:00 | G30: 11 | H30: Migraine | I30: 4 | J30: Dr. Gupta | K30: 44291 | L30: MedB | M30: Yes | N30: Routine | O30: 45242 | P30: 45242.292 | Q30: CT Scan | R30: Accepted | S30: Morning | T30: 4 | U30: 8 | V30: Plan B | Y30: =(T30/U30*100) -> 50
A31: PAT5029 | B31: 42 | C31: ICU | D31: 45031 | E31: =TEXT(D31,"MMM") -> Apr | F31: 17-04-23 0:00 | G31: 2 | H31: Diabetes | I31: 1 | J31: Dr. Sharma | K31: 17397 | L31: MedC | M31: Yes | N31: Routine | O31: 13-04-23 0:00 | P31: 14-04-23 4:00 | Q31: Ultrasound | R31: Accepted | S31: Morning | T31: 8 | U31: 8 | V31: Plan B | Y31: =(T31/U31*100) -> 100
A32: PAT5030 | B32: 60 | C32: General Medicine | D32: 45021 | E32: =TEXT(D32,"MMM") -> Apr | F32: 19-04-23 0:00 | G32: 14 | H32: Hypertension | I32: 1 | J32: Dr. Mehta | K32: 45879 | L32: MedD | M32: No | N32: Routine | O32: 44989 | P32: 44989.625 | Q32: X-Ray | R32: Accepted | S32: Morning | T32: 11 | U32: 10 | V32: Plan B | Y32: =(T32/U32*100) -> 110
A33: PAT5031 | B33: 80 | C33: Neurology | D33: 45316 | E33: =TEXT(D33,"MMM") -> Jan | F33: 45324 | G33: 8 | H33: Diabetes | I33: 3 | J33: Dr. Patel | K33: 40169 | L33: MedB | M33: No | N33: Routine | O33: 20-01-24 0:00 | P33: 20-01-24 5:00 | Q33: Ultrasound | R33: Accepted | S33: Morning | T33: 7 | U33: 8 | V33: Plan C | Y33: =(T33/U33*100) -> 87.5
A34: PAT5032 | B34: 15 | C34: Emergency | D34: 45026 | E34: =TEXT(D34,"MMM") -> Apr | F34: 20-04-23 0:00 | G34: 10 | H34: Hypertension | I34: 2 | J34: Dr. Mehta | K34: 31940 | L34: MedB | M34: Yes | N34: Emergency | O34: 45111 | P34: 45111.917 | Q34: MRI | R34: Rejected | S34: Night | T34: 8 | U34: 8 | V34: Plan B | Y34: =(T34/U34*100) -> 100
A35: PAT5033 | B35: 62 | C35: Neurology | D35: 45294 | E35: =TEXT(D35,"MMM") -> Jan | F35: 45566 | G35: 7 | H35: Hypertension | I35: 4 | J35: Dr. Sharma | K35: 47249 | L35: MedD | M35: No | N35: Routine | O35: 45323 | P35: 45352.625 | Q35: Blood Test | R35: Accepted | S35: Afternoon | T35: 5 | U35: 12 | V35: Plan A | Y35: =(T35/U35*100) -> 41.666667
A36: PAT5034 | B36: 62 | C36: Cardiology | D36: 45279 | E36: =TEXT(D36,"MMM") -> Dec | F36: 24-12-23 0:00 | G36: 5 | H36: Flu | I36: 3 | J36: Dr. Mehta | K36: 33341 | L36: MedE | M36: No | N36: Routine | O36: 15-12-23 0:00 | P36: 16-12-23 16:00 | Q36: MRI | R36: Accepted | S36: Morning | T36: 9 | U36: 8 | V36: Plan C | Y36: =(T36/U36*100) -> 112.5
A37: PAT5035 | B37: 47 | C37: ICU | D37: 45197 | E37: =TEXT(D37,"MMM") -> Sep | F37: 29-09-23 0:00 | G37: 1 | H37: Migraine | I37: 1 | J37: Dr. Sharma | K37: 15067 | L37: MedD | M37: No | N37: Emergency | O37: 26-09-23 0:00 | P37: 27-09-23 15:00 | Q37: Blood Test | R37: Accepted | S37: Night | T37: 10 | U37: 10 | V37: Plan C | Y37: =(T37/U37*100) -> 100
A38: PAT5036 | B38: 62 | C38: General Medicine | D38: 37666 | E38: =TEXT(D38,"MMM") -> Feb | F38: 26-02-23 0:00 | G38: 12 | H38: Migraine | I38: 5 | J38: Dr. Rao | K38: 18824 | L38: MedC | M38: No | N38: Emergency | O38: 45171 | P38: 45201.083 | Q38: Ultrasound | R38: Accepted | S38: Morning | T38: 11 | U38: 8 | V38: Plan C | Y38: =(T38/U38*100) -> 137.5
A39: PAT5037 | B39: 51 | C39: Neurology | D39: 45397 | E39: =TEXT(D39,"MMM") -> Apr | F39: 21-04-24 0:00 | G39: 6 | H39: Hypertension | I39: 2 | J39: Dr. Patel | K39: 18444 | L39: MedE | M39: No | N39: Routine | O39: 45630 | P39: 45630.875 | Q39: CT Scan | R39: Accepted | S39: Night | T39: 11 | U39: 12 | V39: Plan C | Y39: =(T39/U39*100) -> 91.666667
A40: PAT5038 | B40: 55 | C40: ICU | D40: 45054 | E40: =TEXT(D40,"MMM") -> May | F40: 45265 | G40: 4 | H40: Fracture | I40: 5 | J40: Dr. Sharma | K40: 38307 | L40: MedA | M40: No | N40: Routine | O40: 45112 | P40: 45112.083 | Q40: Ultrasound | R40: Accepted | S40: Morning | T40: 7 | U40: 10 | V40: Plan C | Y40: =(T40/U40*100) -> 70
...

Sheet Objective
A1: Healthcare Analytics Questions
A2: 1. What is the average length of hospital stay for different age groups?
A3: 2. Which departments have the highest patient inflow per month?
A4: 3. Which diseases or conditions are most frequently diagnosed?
A5: 4. What is the average treatment cost for different diseases?
A6: 5. Is there a seasonal trend in the number of hospital admissions?
A7: 6. Which medications are most commonly prescribed by department?
A8: 7. What percentage of patients have insurance coverage?
A9: 8. How many emergency cases were handled in the last 12 months?
A10: Operational & Quality Control Questions
A11: 9. What is the doctor-to-patient ratio in each department?
A12: 10. Which diagnostic tests have the highest rejection or error rate?
... A14: 12. How does staff utilization rate vary by shift and department?

Sheet Answer
A1: Q1. | B1: 1=11 | C1: =AVERAGE(Healthcare_LifeSciences_Data!G13:G993) -> 7.9255861
A2: Some Question which are important, those answers are written in data sheet | B2: 12=22 | C2: =AVERAGE(Healthcare_LifeSciences_Data!G3:G1001) -> 7.8638639
B3: 23=33 | C3: =AVERAGE(Healthcare_LifeSciences_Data!G12:G991) -> 7.9163265
B4: 34=45 | C4: =AVERAGE(Healthcare_LifeSciences_Data!G19:G1000) -> 7.9093686
B5: 46=56 | C5: =AVERAGE(Healthcare_LifeSciences_Data!G2:G967) -> 7.8612836
B6: 57=67 | C6: =AVERAGE(Healthcare_LifeSciences_Data!G5:G992) -> 7.8876518
B7: 68=78 | C7: =AVERAGE(Healthcare_LifeSciences_Data!G4:G999) -> 7.8684739
B8: 79=89 | C8: =AVERAGE(Healthcare_LifeSciences_Data!G7:G996) -> 7.8818182
A10: Q4. | B10: Disease | C10: Average Treatment Cost
B11: Diabetes | C11: =AVERAGE(Healthcare_LifeSciences_Data!K6:K997) -> 26699.59
B12: Flu | C12: =AVERAGE(Healthcare_LifeSciences_Data!K8:K994) -> 26720.217
B13: Fracture | C13: =AVERAGE(Healthcare_LifeSciences_Data!K3:K991) -> 26724.133
B14: Heart Disease | C14: =AVERAGE(Healthcare_LifeSciences_Data!K2:K1001) -> 26785.049
B15: Hypertension | C15: =AVERAGE(Healthcare_LifeSciences_Data!K4:K995) -> 26682.659
B16: Migraine | C16: =AVERAGE(Healthcare_LifeSciences_Data!K11:K999) -> 26718.779
A18: Q7. | B18: =COUNTIF(Healthcare_LifeSciences_Data!M2:M1001,"YES") -> 617 | C18: =B18/B19*100 -> 61.7
B19: =COUNTA(Healthcare_LifeSciences_Data!M2:M1001) -> 1000
A21: Q10. | B21: =COUNTIFS(Healthcare_LifeSciences_Data!Q2:Q1001,Healthcare_LifeSciences_Data!Q2,Healthcare_LifeSciences_Data!R2:R1001,Healthcare_LifeSciences_Data!R3) -> 18 | C21: X-Ray
B22: =COUNTIFS(Healthcare_LifeSciences_Data!Q2:Q1001,Healthcare_LifeSciences_Data!Q3,Healthcare_LifeSciences_Data!R2:R1001,Healthcare_LifeSciences_Data!R4) -> 13 | C22: Blood Test
B23: =COUNTIFS(Healthcare_LifeSciences_Data!Q2:Q1001,Healthcare_LifeSciences_Data!Q4,Healthcare_LifeSciences_Data!R2:R1001,Healthcare_LifeSciences_Data!R3) -> 17 | C23: CT Scan
B24: =COUNTIFS(Healthcare_LifeSciences_Data!Q2:Q1001,Healthcare_LifeSciences_Data!Q7,Healthcare_LifeSciences_Data!R2:R1001,Healthcare_LifeSciences_Data!R4) -> 19 | C24: Ultrasound
B25: =COUNTIFS(Healthcare_LifeSciences_Data!Q2:Q1001,Healthcare_LifeSciences_Data!Q11,Healthcare_LifeSciences_Data!R2:R1001,Healthcare_LifeSciences_Data!R3) -> 22 | C25: MRI

Sheet Q2
A1: Count of Admission Date | B1: Column Labels
A2: Row Labels | B2: 13-01-23 0:00 | C2: 13-01-24 0:00 | D2: 13-02-23 0:00 | E2: 13-02-24 0:00 | F2: 13-03-23 0:00 | G2: 13-03-24 0:00 | H2: 13-04-23 0:00 | I2: 13-04-24 0:00 | J2: 13-05-23 0:00 | K2: 13-05-24 0:00 | L2: 13-07-23 0:00 | M2: 13-09-23 0:00 | N2: 13-10-23 0:00 | O2: 13-11-23 0:00 | P2: 13-12-23 0:00 | Q2: 14-01-23 0:00 | R2: 14-02-23 0:00 | S2: 14-02-24 0:00 | T2: 14-03-23 0:00 | U2: 14-03-24 0:00 | V2: 14-04-23 0:00 | W2: 14-04-24 0:00 | X2: 14-05-23 0:00 | Y2: 14-05-24 0:00 | Z2: 14-06-23 0:00 | AA2: 14-08-23 0:00 | AB2: 14-09-23 0:00 | AC2: 14-10-23 0:00 | AD2: 14-11-23 0:00 | AE2: 14-12-23 0:00 | AF2: 15-01-23 0:00 | AG2: 15-01-24 0:00 | AH2: 15-02-23 0:00 | AI2: 15-02-24 0:00 | AJ2: 15-03-23 0:00 | AK2: 15-03-24 0:00 | AL2: 15-04-23 0:00 | AM2: 15-04-24 0:00 | AN2: 15-05-23 0:00 | AO2: 15-05-24 0:00 | AP2: 15-06-23 0:00 | AQ2: 15-07-23 0:00 | AR2: 15-08-23 0:00 | AS2: 15-09-23 0:00 | AT2: 15-10-23 0:00 | AU2: 15-11-23 0:00 | AV2: 15-12-23 0:00 | AW2: 16-01-23 0:00 | AX2: 16-01-24 0:00 | AY2: 16-02-24 0:00 | AZ2: 16-03-23 0:00 | BA2: 16-03-24 0:00 | BB2: 16-04-23 0:00 | BC2: 16-04-24 0:00 | BD2: 16-05-23 0:00 | BE2: 16-05-24 0:00 | BF2: 16-06-23 0:00 | BG2: 16-06-24 0:00 | BH2: 16-07-23 0:00 | BI2: 16-08-23 0:00 | BJ2: 16-09-23 0:00 | BK2: 16-12-23 0:00 | BL2: 17-01-23 0:00 | BM2: 17-01-24 0:00 | BN2: 17-02-24 0:00 | BO2: 17-03-23 0:00 | BP2: 17-03-24 0:00 | BQ2: 17-04-23 0:00 | BR2: 17-04-24 0:00 | BS2: 17-05-23 0:00 | BT2: 17-05-24 0:00 | BU2: 17-06-23 0:00 | BV2: 17-06-24 0:00 | BW2: 17-07-23 0:00 | BX2: 17-08-23 0:00 | BY2: 17-09-23 0:00 | BZ2: 17-10-23 0:00 | CA2: 17-11-23 0:00 | CB2: 18-01-23 0:00 | CC2: 18-02-24 0:00 | CD2: 18-03-23 0:00 | CE2: 18-04-23 0:00 | CF2: 18-04-24 0:00 | CG2: 18-05-23 0:00 | CH2: 18-05-24 0:00 | CI2: 18-06-23 0:00 | CJ2: 18-06-24 0:00 | CK2: 18-08-23 0:00 | CL2: 18-09-23 0:00 | CM2: 18-10-23 0:00 | CN2: 18-11-23 0:00 | CO2: 18-12-23 0:00 | CP2: 19-01-23 0:00 | CQ2: 19-01-24 0:00 | CR2: 19-02-23 0:00 | CS2: 19-02-24 0:00 | CT2: 19-04-23 0:00 | CU2: 19-05-23 0:00 | CV2: 19-06-23 0:00 | CW2: 19-06-24 0:00 | CX2: 19-07-23 0:00 | CY2: 19-08-23 0:00 | CZ2: 19-09-23 0:00 | DA2: 19-10-23 0:00 | DB2: 19-11-23 0:00 | DC2: 19-12-23 0:00 | DD2: 20-01-23 0:00 | DE2: 20-01-24 0:00 | DF2: 20-02-24 0:00 | DG2: 20-03-23 0:00 | DH2: 20-03-24 0:00 | DI2: 20-04-23 0:00 | DJ2: 20-04-24 0:00 | DK2: 20-05-23 0:00 | DL2: 20-05-24 0:00 | DM2: 20-06-23 0:00 | DN2: 20-06-24 0:00 | DO2: 20-08-23 0:00 | DP2: 20-09-23 0:00 | DQ2: 20-10-23 0:00 | DR2: 20-11-23 0:00 | DS2: 20-12-23 0:00 | DT2: 21-01-23 0:00 | DU2: 21-01-24 0:00 | DV2: 21-02-24 0:00 | DW2: 21-03-23 0:00 | DX2: 21-03-24 0:00 | DY2: 21-04-23 0:00 | DZ2: 21-04-24 0:00 | EA2: 21-05-23 0:00 | EB2: 21-05-24 0:00 | EC2: 21-06-23 0:00 | ED2: 21-06-24 0:00 | EE2: 21-07-23 0:00 | EF2: 21-08-23 0:00 | EG2: 21-09-23 0:00 | EH2: 21-10-23 0:00 | EI2: 21-11-23 0:00 | EJ2: 21-12-23 0:00 | EK2: 22-01-24 0:00 | EL2: 22-02-23 0:00 | EM2: 22-02-24 0:00 | EN2: 22-03-23 0:00 | EO2: 22-03-24 0:00 | EP2: 22-04-24 0:00 | EQ2: 22-05-23 0:00 | ER2: 22-05-24 0:00 | ES2: 22-06-23 0:00 | ET2: 22-07-23 0:00 | EU2: 22-08-23 0:00 | EV2: 22-09-23 0:00 | EW2: 22-10-23 0:00 | EX2: 22-11-23 0:00 | EY2: 22-12-23 0:00 | EZ2: 23-01-23 0:00 | FA2: 23-01-24 0:00 | FB2: 23-02-23 0:00 | FC2: 23-02-24 0:00 | FD2: 23-03-23 0:00 | FE2: 23-03-24 0:00 | FF2: 23-04-23 0:00 | FG2: 23-04-24 0:00 | FH2: 23-05-23 0:00 | FI2: 23-05-24 0:00 | FJ2: 23-06-23 0:00 | FK2: 23-06-24 0:00 | FL2: 23-07-23 0:00 | FM2: 23-09-23 0:00 | FN2: 23-10-23 0:00 | FO2: 23-11-23 0:00 | FP2: 23-12-23 0:00 | FQ2: 24-01-24 0:00 | FR2: 24-02-23 0:00 | FS2: 24-02-24 0:00 | FT2: 24-03-23 0:00 | FU2: 24-04-23 0:00 | FV2: 24-04-24 0:00 | FW2: 24-05-23 0:00 | FX2: 24-05-24 0:00 | FY2: 24-06-23 0:00 | FZ2: 24-06-24 0:00 | GA2: 24-07-23 0:00 | GB2: 24-09-23 0:00 | GC2: 24-10-23 0:00 | GD2: 24-11-23 0:00 | GE2: 24-12-23 0:00 | GF2: 25-01-23 0:00 | GG2: 25-01-24 0:00 | GH2: 25-02-23 0:00 | GI2: 25-02-24 0:00 | GJ2: 25-03-23 0:00 | GK2: 25-03-24 0:00 | GL2: 25-04-24 0:00 | GM2: 25-05-24 0:00 | GN2: 25-06-23 0:00 | GO2: 25-06-24 0:00 | GP2: 25-07-23 0:00 | GQ2: 25-08-23 0:00 | GR2: 25-09-23 0:00 | GS2: 25-10-23 0:00 | GT2: 25-11-23 0:00 | GU2: 26-01-23 0:00 | GV2: 26-01-24 0:00 | GW2: 26-02-23 0:00 | GX2: 26-03-23 0:00 | GY2: 26-03-24 0:00 | GZ2: 26-04-23 0:00 | HA2: 26-04-24 0:00 | HB2: 26-05-23 0:00 | HC2: 26-05-24 0:00 | HD2: 26-06-23 0:00 | HE2: 26-07-23 0:00 | HF2: 26-08-23 0:00 | HG2: 26-09-23 0:00 | HH2: 26-10-23 0:00 | HI2: 26-12-23 0:00 | HJ2: 27-01-24 0:00 | HK2: 27-02-23 0:00 | HL2: 27-02-24 0:00 | HM2: 27-03-23 0:00 | HN2: 27-03-24 0:00 | HO2: 27-04-23 0:00 | HP2: 27-04-24 0:00 | HQ2: 27-05-23 0:00 | HR2: 27-05-24 0:00 | HS2: 27-06-24 0:00 | HT2: 27-08-23 0:00 | HU2: 27-09-23 0:00 | HV2: 27-11-23 0:00 | HW2: 27-12-23 0:00 | HX2: 28-01-23 0:00 | HY2: 28-01-24 0:00 | HZ2: 28-02-23 0:00 | IA2: 28-02-24 0:00 | IB2: 28-03-23 0:00 | IC2: 28-03-24 0:00 | ID2: 28-04-23 0:00 | IE2: 28-04-24 0:00 | IF2: 28-05-23 0:00 | IG2: 28-06-23 0:00 | IH2: 28-06-24 0:00 | II2: 28-07-23 0:00 | IJ2: 28-08-23 0:00 | IK2: 28-09-23 0:00 | IL2: 28-11-23 0:00 | IM2: 28-12-23 0:00 | IN2: 29-01-23 0:00 | IO2: 29-01-24 0:00 | IP2: 29-02-24 0:00 | IQ2: 29-03-23 0:00 | IR2: 29-03-24 0:00 | IS2: 29-04-23 0:00 | IT2: 29-04-24 0:00 | IU2: 29-05-23 0:00 | IV2: 29-05-24 0:00 | IW2: 29-06-23 0:00 | IX2: 29-07-23 0:00 | IY2: 29-08-23 0:00 | IZ2: 29-09-23 0:00 | JA2: 29-10-23 0:00 | JB2: 29-11-23 0:00 | JC2: 29-12-23 0:00 | JD2: 30-01-23 0:00 | JE2: 30-01-24 0:00 | JF2: 30-03-23 0:00 | JG2: 30-04-23 0:00 | JH2: 30-04-24 0:00 | JI2: 30-06-24 0:00 | JJ2: 30-07-23 0:00 | JK2: 30-08-23 0:00 | JL2: 30-09-23 0:00 | JM2: 30-10-23 0:00 | JN2: 30-11-23 0:00 | JO2: 30-12-23 0:00 | JP2: 31-01-23 0:00 | JQ2: 31-01-24 0:00 | JR2: 31-03-23 0:00 | JS2: 31-03-24 0:00 | JT2: 31-05-23 0:00 | JU2: 31-05-24 0:00 | JV2: 31-07-23 0:00 | JW2: 31-08-23 0:00 | JX2: 44928 | JY2: 44929 | JZ2: 44931 | KA2: 44933 | KB2: 44934 | KC2: 44935 | KD2: 44936 | KE2: 44937 | KF2: 44959 | KG2: 44960 | KH2: 44961 | KI2: 44962 | KJ2: 44963 | KK2: 44965 | KL2: 44966 | KM2: 44968 | KN2: 44969 | KO2: 44987 | KP2: 44988 | KQ2: 44989 | KR2: 44990 | KS2: 44991 | KT2: 44992 | KU2: 44994 | KV2: 44995 | KW2: 44996 | KX2: 44997 | KY2: 45018 | KZ2: 45019 | LA2: 45020 | LB2: 45021 | LC2: 45024 | LD2: 45025 | LE2: 45026 | LF2: 45027 | LG2: 45028 | LH2: 45047 | LI2: 45048 | LJ2: 45049 | LK2: 45050 | LL2: 45051 | LM2: 45052 | LN2: 45053 | LO2: 45055 | LP2: 45056 | LQ2: 45057 | LR2: 45058 | LS2: 45079 | LT2: 45081 | LU2: 45082 | LV2: 45083 | LW2: 45084 | LX2: 45086 | LY2: 45087 | LZ2: 45088 | MA2: 45089 | MB2: 45109 | MC2: 45110 | MD2: 45111 | ME2: 45113 | MF2: 45114 | MG2: 45115 | MH2: 45116 | MI2: 45117 | MJ2: 45118 | MK2: 45119 | ML2: 45139 | MM2: 45142 | MN2: 45143 | MO2: 45144 | MP2: 45145 | MQ2: 45146 | MR2: 45147 | MS2: 45148 | MT2: 45149 | MU2: 45150 | MV2: 45171 | MW2: 45172 | MX2: 45174 | MY2: 45175 | MZ2: 45176 | NA2: 45177 | NB2: 45178 | NC2: 45179 | ND2: 45180 | NE2: 45181 | NF2: 45200 | NG2: 45202 | NH2: 45203 | NI2: 45204 | NJ2: 45205 | NK2: 45207 | NL2: 45208 | NM2: 45209 | NN2: 45210 | NO2: 45211 | NP2: 45231 | NQ2: 45232 | NR2: 45233 | NS2: 45234 | NT2: 45235 | NU2: 45236 | NV2: 45238 | NW2: 45239 | NX2: 45240 | NY2: 45241 | NZ2: 45242 | OA2: 45261 | OB2: 45262 | OC2: 45263 | OD2: 45264 | OE2: 45265 | OF2: 45266 | OG2: 45267 | OH2: 45268 | OI2: 45270 | OJ2: 45271 | OK2: 45272 | OL2: 45292 | OM2: 45294 | ON2: 45295 | OO2: 45296 | OP2: 45324 | OQ2: 45325 | OR2: 45326 | OS2: 45327 | OT2: 45328 | OU2: 45329 | OV2: 45352 | OW2: 45353 | OX2: 45354 | OY2: 45355 | OZ2: 45356 | PA2: 45357 | PB2: 45383 | PC2: 45384 | PD2: 45385 | PE2: 45386 | PF2: 45387 | PG2: 45388 | PH2: 45413 | PI2: 45414 | PJ2: 45415 | PK2: 45416 | PL2: 45417 | PM2: 45418 | PN2: 45445 | PO2: 45446 | PP2: 45447 | PQ2: 45448 | PR2: 45449 | PS2: 45450 | PT2: 45475 | PU2: 45476 | PV2: 45477 | PW2: 45478 | PX2: 45479 | PY2: 45505 | PZ2: 45506 | QA2: 45507 | QB2: 45508 | QC2: 45509 | QD2: 45510 | QE2: 45537 | QF2: 45538 | QG2: 45539 | QH2: 45540 | QI2: 45541 | QJ2: 45566 | QK2: 45567 | QL2: 45568 | QM2: 45569 | QN2: 45571 | QO2: 45597 | QP2: 45598 | QQ2: 45599 | QR2: 45600 | QS2: 45601 | QT2: 45602 | QU2: 45628 | QV2: 45629 | QW2: 45630 | QX2: 45631 | QY2: 45632 | QZ2: Grand Total
A3: Cardiology | B3: 1 | I3: 1 | W3: 1 | Y3: 1 | Z3: 2 | AC3: 1 | AF3: 1 | AG3: 1 | AI3: 1 | AS3: 1 | AX3: 1 | BA3: 1 | BF3: 1 | BH3: 1 | BN3: 1 | BR3: 1 | BS3: 1 | BT3: 2 | BZ3: 1 | CA3: 1 | CK3: 1 | CL3: 1 | CM3: 1 | CP3: 1 | CU3: 1 | CV3: 1 | CZ3: 2 | DA3: 1 | DF3: 1 | DG3: 1 | DH3: 1 | DI3: 1 | DJ3: 1 | DK3: 1 | DL3: 1 | DO3: 2 | DP3: 1 | DU3: 1 | DW3: 1 | DY3: 2 | EA3: 1 | EB3: 1 | EF3: 2 | EH3: 2 | EI3: 1 | EO3: 1 | EW3: 1 | EX3: 1 | EZ3: 1 | FA3: 1 | FB3: 1 | FC3: 2 | FE3: 1 | FG3: 1 | FI3: 1 | FJ3: 1 | FK3: 1 | FL3: 1 | FN3: 1 | FQ3: 1 | FS3: 1 | FW3: 1 | GA3: 1 | GC3: 1 | GD3: 2 | GE3: 1 | GI3: 1 | GK3: 1 | GP3: 1 | GT3: 1 | GU3: 1 | GV3: 1 | GZ3: 1 | HA3: 1 | HB3: 1 | HD3: 1 | HE3: 1 | HK3: 1 | HP3: 1 | HQ3: 1 | HT3: 1 | HV3: 1 | HZ3: 1 | IC3: 1 | IG3: 1 | IJ3: 2 | IM3: 1 | IP3: 1 | IR3: 1 | IX3: 2 | JF3: 1 | JH3: 1 | JL3: 1 | JM3: 1 | JQ3: 1 | JR3: 1 | KB3: 1 | KH3: 1 | KI3: 1 | KM3: 1 | KQ3: 1 | KT3: 1 | KV3: 2 | KW3: 1 | KX3: 1 | KZ3: 2 | LL3: 1 | LM3: 1 | LN3: 2 | LT3: 1 | LW3: 1 | LY3: 2 | MA3: 1 | MB3: 1 | MD3: 2 | MG3: 1 | MM3: 1 | MN3: 1 | MX3: 1 | NC3: 1 | ND3: 2 | NJ3: 1 | NK3: 1 | NN3: 1 | NO3: 1 | NQ3: 1 | NV3: 1 | NY3: 1 | OB3: 1 | OI3: 1 | OJ3: 1 | OQ3: 2 | OS3: 1 | OY3: 1 | PA3: 1 | PC3: 1 | PH3: 1 | PL3: 1 | PN3: 1 | PT3: 1 | PY3: 1 | PZ3: 1 | QA3: 1 | QE3: 1 | QP3: 1 | QV3: 1 | QY3: 1 | QZ3: 165
A4: Emergency | C4: 1 | E4: 1 | F4: 1 | L4: 1 | M4: 2 | Q4: 1 | R4: 1 | S4: 1 | T4: 1 | Y4: 1 | Z4: 1 | AD4: 2 | AH4: 1 | AM4: 1 | AP4: 2 | AQ4: 1 | AR4: 1 | AT4: 1 | AZ4: 1 | BA4: 1 | BB4: 1 | BD4: 1 | BH4: 1 | BJ4: 1 | BP4: 1 | BR4: 1 | BS4: 1 | BT4: 1 | BU4: 1 | BV4: 2 | BX4: 2 | CB4: 1 | CD4: 1 | CG4: 1 | CK4: 2 | CN4: 1 | CS4: 1 | CW4: 1 | CY4: 1 | DB4: 1 | DF4: 1 | DH4: 1 | DI4: 1 | DW4: 1 | DY4: 1 | EE4: 1 | EI4: 1 | EQ4: 1 | ER4: 1 | ET4: 1 | EV4: 1 | EW4: 1 | EX4: 1 | FC4: 1 | FH4: 1 | FI4: 1 | FP4: 2 | FS4: 1 | FY4: 1 | GD4: 1 | GE4: 1 | GJ4: 1 | GK4: 1 | GP4: 1 | HA4: 1 | HD4: 3 | HF4: 1 | HK4: 1 | HM4: 1 | HN4: 1 | HQ4: 1 | HW4: 1 | HX4: 2 | IA4: 1 | IB4: 1 | IF4: 1 | IJ4: 1 | IM4: 1 | IT4: 1 | JD4: 1 | JE4: 1 | JG4: 1 | JH4: 1 | JI4: 2 | JK4: 1 | JL4: 2 | JN4: 1 | JQ4: 1 | JS4: 1 | JT4: 3 | JY4: 1 | JZ4: 1 | KD4: 1 | KE4: 1 | KK4: 1 | KQ4: 1 | KS4: 1 | KT4: 1 | KU4: 1 | LB4: 1 | LF4: 1 | LG4: 1 | LK4: 1 | LL4: 1 | LP4: 1 | LR4: 1 | LT4: 2 | LU4: 1 | MB4: 1 | MF4: 1 | MH4: 1 | MM4: 1 | MV4: 2 | NF4: 1 | NK4: 1 | NO4: 2 | NP4: 1 | NT4: 1 | NU4: 1 | NV4: 1 | OD4: 1 | OG4: 1 | OJ4: 1 | OK4: 1 | OM4: 1 | OP4: 2 | OQ4: 1 | PC4: 1 | PD4: 1 | PE4: 2 | PG4: 1 | PI4: 1 | PK4: 1 | PM4: 1 | PN4: 1 | PO4: 1 | PQ4: 1 | PR4: 1 | PY4: 1 | PZ4: 1 | QF4: 2 | QI4: 1 | QK4: 1 | QM4: 1 | QN4: 1 | QS4: 1 | QZ4: 166
A5: General Medicine | I5: 1 | J5: 2 | P5: 1 | S5: 1 | U5: 1 | V5: 1 | AD5: 2 | AH5: 1 | AJ5: 1 | AM5: 1 | AN5: 2 | AQ5: 1 | AT5: 1 | AV5: 2 | BB5: 1 | BE5: 2 | BF5: 1 | BI5: 1 | BJ5: 1 | BP5: 1 | BQ5: 1 | BU5: 1 | BY5: 1 | CA5: 1 | CC5: 1 | CF5: 3 | CN5: 1 | CO5: 2 | CS5: 1 | CT5: 1 | CV5: 1 | CW5: 1 | DA5: 1 | DI5: 1 | DL5: 1 | DM5: 1 | DP5: 1 | DQ5: 1 | DS5: 1 | DU5: 1 | DX5: 1 | EC5: 1 | EE5: 1 | EG5: 1 | EH5: 1 | EI5: 1 | EN5: 1 | EQ5: 1 | ER5: 1 | ET5: 1 | EU5: 1 | FC5: 1 | FD5: 1 | FE5: 1 | FF5: 1 | FN5: 1 | FO5: 1 | FP5: 1 | FT5: 1 | FY5: 1 | GA5: 1 | GB5: 2 | GE5: 2 | GG5: 2 | GI5: 1 | GM5: 1 | GO5: 1 | GT5: 1 | GV5: 1 | GW5: 1 | HA5: 1 | HC5: 1 | HF5: 2 | HG5: 1 | HJ5: 1 | HM5: 1 | HO5: 1 | HP5: 2 | HU5: 1 | HW5: 2 | IC5: 1 | ID5: 1 | IE5: 1 | IH5: 1 | IN5: 1 | IO5: 1 | IS5: 1 | IT5: 1 | IU5: 1 | IY5: 1 | JC5: 1 | JK5: 1 | JM5: 1 | JO5: 1 | JP5: 2 | JS5: 1 | KI5: 1 | KN5: 2 | KP5: 1 | KW5: 1 | KX5: 1 | KY5: 2 | LA5: 1 | LD5: 2 | LG5: 1 | LH5: 1 | LI5: 2 | LJ5: 1 | LM5: 1 | LP5: 1 | LS5: 1 | LV5: 1 | MC5: 1 | ME5: 1 | MF5: 1 | MP5: 1 | MQ5: 1 | MR5: 2 | MS5: 2 | MT5: 1 | MU5: 1 | MV5: 1 | NB5: 1 | NC5: 1 | NG5: 1 | NH5: 1 | NJ5: 1 | NN5: 1 | NQ5: 3 | NR5: 2 | NT5: 1 | NW5: 2 | NX5: 1 | NY5: 1 | NZ5: 2 | OA5: 1 | OI5: 1 | OL5: 1 | OR5: 1 | OZ5: 1 | PD5: 1 | PG5: 1 | PO5: 1 | PY5: 1 | QB5: 1 | QD5: 2 | QG5: 1 | QJ5: 1 | QL5: 1 | QN5: 1 | QT5: 1 | QU5: 1 | QX5: 2 | QZ5: 181
A6: ICU | D6: 1 | E6: 1 | F6: 3 | H6: 1 | M6: 1 | N6: 1 | Q6: 1 | W6: 2 | X6: 1 | Z6: 2 | AB6: 1 | AE6: 1 | AL6: 1 | AS6: 1 | AU6: 1 | BB6: 1 | BC6: 1 | BD6: 1 | BG6: 1 | BJ6: 1 | BM6: 1 | BQ6: 1 | BX6: 1 | BY6: 1 | CA6: 1 | CB6: 1 | CK6: 1 | CN6: 2 | CP6: 1 | CQ6: 1 | CR6: 1 | CS6: 1 | CX6: 1 | DA6: 1 | DE6: 1 | DJ6: 1 | DN6: 1 | DQ6: 2 | DR6: 1 | DT6: 1 | DW6: 2 | EI6: 1 | EN6: 1 | EO6: 1 | ER6: 1 | ES6: 1 | ET6: 1 | FB6: 1 | FD6: 2 | FE6: 1 | FG6: 2 | FJ6: 1 | FL6: 1 | FO6: 2 | FT6: 1 | FU6: 1 | FV6: 1 | FX6: 1 | FY6: 2 | FZ6: 2 | GF6: 2 | GJ6: 1 | GK6: 1 | GS6: 2 | GU6: 1 | GW6: 1 | HE6: 2 | HF6: 1 | HH6: 2 | HI6: 1 | HJ6: 2 | HK6: 2 | HS6: 1 | HY6: 1 | IE6: 1 | IF6: 1 | II6: 1 | IL6: 1 | IQ6: 1 | IR6: 1 | IT6: 1 | IW6: 1 | IY6: 1 | IZ6: 2 | JA6: 2 | JF6: 1 | JJ6: 1 | JL6: 1 | JU6: 1 | JV6: 1 | JW6: 1 | JX6: 2 | JZ6: 2 | KD6: 1 | KE6: 1 | KF6: 1 | KL6: 1 | KN6: 1 | KP6: 2 | KQ6: 1 | KR6: 1 | KV6: 1 | LD6: 1 | LH6: 1 | LO6: 1 | LP6: 1 | LQ6: 1 | LX6: 1 | LY6: 1 | LZ6: 1 | MD6: 1 | MF6: 1 | MJ6: 1 | MK6: 1 | MM6: 1 | MO6: 1 | MV6: 1 | MW6: 1 | MZ6: 1 | NC6: 1 | NE6: 1 | NG6: 1 | NI6: 1 | NL6: 1 | NM6: 1 | NZ6: 2 | OC6: 1 | OD6: 1 | OE6: 2 | OH6: 2 | OI6: 2 | OO6: 1 | OT6: 1 | OX6: 1 | PD6: 1 | PE6: 2 | PH6: 1 | PJ6: 1 | PL6: 1 | PM6: 2 | PQ6: 1 | QD6: 1 | QH6: 1 | QL6: 1 | QO6: 1 | QQ6: 1 | QS6: 2 | QW6: 2 | QZ6: 179
A7: Neurology | C7: 1 | G7: 1 | J7: 1 | L7: 1 | O7: 1 | R7: 2 | T7: 1 | AA7: 1 | AB7: 2 | AC7: 1 | AD7: 1 | AH7: 2 | AL7: 1 | AO7: 1 | AW7: 1 | AY7: 1 | BE7: 1 | BF7: 2 | BG7: 1 | BH7: 2 | BJ7: 2 | BK7: 1 | BL7: 1 | BN7: 1 | BO7: 1 | BP7: 1 | BU7: 1 | BY7: 2 | BZ7: 1 | CJ7: 1 | CK7: 1 | CV7: 1 | CX7: 1 | CY7: 2 | DA7: 1 | DC7: 2 | DD7: 1 | DG7: 1 | DH7: 2 | DK7: 1 | DM7: 1 | DO7: 1 | DU7: 1 | DV7: 1 | DY7: 2 | DZ7: 2 | EA7: 1 | EB7: 2 | ED7: 1 | EG7: 1 | EH7: 1 | EJ7: 1 | EK7: 1 | ET7: 1 | EZ7: 1 | FC7: 1 | FG7: 1 | FM7: 1 | FP7: 1 | FR7: 1 | FU7: 1 | FV7: 1 | GD7: 1 | GF7: 1 | GH7: 1 | GK7: 1 | GN7: 1 | GQ7: 1 | GR7: 1 | GV7: 1 | GW7: 1 | GX7: 3 | GY7: 1 | GZ7: 2 | HA7: 1 | HB7: 1 | HE7: 2 | HF7: 1 | HG7: 1 | HL7: 1 | HN7: 1 | HS7: 1 | HW7: 1 | HX7: 2 | IA7: 1 | IB7: 2 | IE7: 2 | IG7: 1 | IM7: 1 | IN7: 1 | IO7: 1 | IS7: 1 | IY7: 2 | JA7: 1 | JG7: 1 | JN7: 2 | JS7: 1 | JV7: 1 | KA7: 1 | KB7: 1 | KG7: 1 | KL7: 2 | KM7: 1 | KS7: 1 | KT7: 1 | KV7: 1 | KZ7: 1 | LB7: 1 | LC7: 1 | LE7: 1 | LH7: 1 | LN7: 1 | LU7: 3 | LZ7: 1 | MC7: 1 | ML7: 1 | MT7: 1 | NA7: 1 | NE7: 1 | NJ7: 1 | NK7: 1 | NL7: 1 | NM7: 1 | NT7: 1 | NV7: 1 | NX7: 1 | ON7: 1 | OP7: 1 | OR7: 1 | OV7: 1 | OW7: 1 | OY7: 1 | OZ7: 2 | PG7: 2 | PH7: 1 | PI7: 1 | PJ7: 1 | PM7: 1 | PN7: 1 | PU7: 1 | QB7: 1 | QC7: 1 | QF7: 1 | QG7: 1 | QJ7: 1 | QY7: 1 | QZ7: 173
A8: Orthopedics | C8: 1 | K8: 1 | O8: 1 | S8: 1 | T8: 1 | U8: 2 | V8: 1 | W8: 1 | AH8: 1 | AJ8: 2 | AK8: 1 | AS8: 1 | AY8: 1 | BA8: 2 | BB8: 1 | BJ8: 1 | BN8: 1 | BP8: 1 | BR8: 1 | BS8: 1 | BW8: 1 | BY8: 1 | CE8: 1 | CF8: 1 | CH8: 1 | CI8: 1 | CL8: 1 | CM8: 1 | CO8: 1 | CV8: 1 | CX8: 1 | CZ8: 1 | DC8: 1 | DP8: 1 | DT8: 1 | DU8: 1 | DW8: 1 | DY8: 1 | DZ8: 1 | ED8: 1 | EF8: 1 | EL8: 1 | EM8: 1 | EO8: 1 | EP8: 1 | EW8: 1 | EY8: 1 | FH8: 1 | FI8: 1 | FM8: 1 | FP8: 1 | FQ8: 1 | FT8: 1 | GB8: 1 | GC8: 1 | GD8: 1 | GL8: 1 | GM8: 2 | GW8: 1 | GZ8: 1 | HB8: 1 | HC8: 2 | HF8: 1 | HG8: 1 | HH8: 1 | HK8: 1 | HP8: 1 | HR8: 1 | IG8: 1 | IK8: 1 | IM8: 1 | IO8: 1 | IS8: 1 | IT8: 1 | IU8: 1 | IV8: 1 | IX8: 1 | IY8: 1 | JB8: 1 | JC8: 1 | JF8: 2 | JM8: 1 | JV8: 1 | KC8: 1 | KJ8: 1 | KO8: 1 | KY8: 1 | LA8: 1 | LD8: 1 | LE8: 1 | LF8: 1 | LO8: 1 | LP8: 1 | LY8: 1 | MA8: 1 | MD8: 1 | ME8: 1 | MH8: 1 | MI8: 1 | ML8: 2 | MS8: 1 | MU8: 2 | MY8: 1 | NR8: 1 | NS8: 1 | OF8: 1 | OI8: 1 | OT8: 1 | OU8: 1 | OW8: 1 | PB8: 1 | PD8: 1 | PF8: 1 | PK8: 1 | PP8: 1 | PR8: 1 | PS8: 1 | PT8: 1 | PU8: 1 | PV8: 1 | PW8: 1 | PX8: 2 | QG8: 1 | QH8: 1 | QL8: 1 | QQ8: 1 | QR8: 1 | QZ8: 136
A9: Grand Total | B9: 1 | C9: 3 | D9: 1 | E9: 2 | F9: 4 | G9: 1 | H9: 1 | I9: 2 | J9: 3 | K9: 1 | L9: 2 | M9: 3 | N9: 1 | O9: 2 | P9: 1 | Q9: 2 | R9: 3 | S9: 3 | T9: 3 | U9: 3 | V9: 2 | W9: 4 | X9: 1 | Y9: 2 | Z9: 5 | AA9: 1 | AB9: 3 | AC9: 2 | AD9: 5 | AE9: 1 | AF9: 1 | AG9: 1 | AH9: 5 | AI9: 1 | AJ9: 3 | AK9: 1 | AL9: 2 | AM9: 2 | AN9: 2 | AO9: 1 | AP9: 2 | AQ9: 2 | AR9: 1 | AS9: 3 | AT9: 2 | AU9: 1 | AV9: 2 | AW9: 1 | AX9: 1 | AY9: 2 | AZ9: 1 | BA9: 4 | BB9: 4 | BC9: 1 | BD9: 2 | BE9: 3 | BF9: 4 | BG9: 2 | BH9: 4 | BI9: 1 | BJ9: 6 | BK9: 1 | BL9: 1 | BM9: 1 | BN9: 3 | BO9: 1 | BP9: 4 | BQ9: 2 | BR9: 3 | BS9: 3 | BT9: 3 | BU9: 3 | BV9: 2 | BW9: 1 | BX9: 3 | BY9: 5 | BZ9: 2 | CA9: 3 | CB9: 2 | CC9: 1 | CD9: 1 | CE9: 1 | CF9: 4 | CG9: 1 | CH9: 1 | CI9: 1 | CJ9: 1 | CK9: 5 | CL9: 2 | CM9: 2 | CN9: 4 | CO9: 3 | CP9: 2 | CQ9: 1 | CR9: 1 | CS9: 3 | CT9: 1 | CU9: 1 | CV9: 4 | CW9: 2 | CX9: 3 | CY9: 3 | CZ9: 3 | DA9: 4 | DB9: 1 | DC9: 3 | DD9: 1 | DE9: 1 | DF9: 2 | DG9: 2 | DH9: 4 | DI9: 3 | DJ9: 2 | DK9: 2 | DL9: 2 | DM9: 2 | DN9: 1 | DO9: 3 | DP9: 3 | DQ9: 3 | DR9: 1 | DS9: 1 | DT9: 2 | DU9: 4 | DV9: 1 | DW9: 5 | DX9: 1 | DY9: 6 | DZ9: 3 | EA9: 2 | EB9: 3 | EC9: 1 | ED9: 2 | EE9: 2 | EF9: 3 | EG9: 2 | EH9: 4 | EI9: 4 | EJ9: 1 | EK9: 1 | EL9: 1 | EM9: 1 | EN9: 2 | EO9: 3 | EP9: 1 | EQ9: 2 | ER9: 3 | ES9: 1 | ET9: 4 | EU9: 1 | EV9: 1 | EW9: 3 | EX9: 2 | EY9: 1 | EZ9: 2 | FA9: 1 | FB9: 2 | FC9: 5 | FD9: 3 | FE9: 3 | FF9: 1 | FG9: 4 | FH9: 2 | FI9: 3 | FJ9: 2 | FK9: 1 | FL9: 2 | FM9: 2 | FN9: 2 | FO9: 3 | FP9: 5 | FQ9: 2 | FR9: 1 | FS9: 2 | FT9: 3 | FU9: 2 | FV9: 2 | FW9: 1 | FX9: 1 | FY9: 4 | FZ9: 2 | GA9: 2 | GB9: 3 | GC9: 2 | GD9: 5 | GE9: 4 | GF9: 3 | GG9: 2 | GH9: 1 | GI9: 2 | GJ9: 2 | GK9: 4 | GL9: 1 | GM9: 3 | GN9: 1 | GO9: 1 | GP9: 2 | GQ9: 1 | GR9: 1 | GS9: 2 | GT9: 2 | GU9: 2 | GV9: 3 | GW9: 4 | GX9: 3 | GY9: 1 | GZ9: 4 | HA9: 4 | HB9: 3 | HC9: 3 | HD9: 4 | HE9: 5 | HF9: 6 | HG9: 3 | HH9: 3 | HI9: 1 | HJ9: 3 | HK9: 5 | HL9: 1 | HM9: 2 | HN9: 2 | HO9: 1 | HP9: 4 | HQ9: 2 | HR9: 1 | HS9: 2 | HT9: 1 | HU9: 1 | HV9: 1 | HW9: 4 | HX9: 4 | HY9: 1 | HZ9: 1 | IA9: 2 | IB9: 3 | IC9: 2 | ID9: 1 | IE9: 4 | IF9: 2 | IG9: 3 | IH9: 1 | II9: 1 | IJ9: 3 | IK9: 1 | IL9: 1 | IM9: 4 | IN9: 2 | IO9: 3 | IP9: 1 | IQ9: 1 | IR9: 2 | IS9: 3 | IT9: 4 | IU9: 2 | IV9: 1 | IW9: 1 | IX9: 3 | IY9: 5 | IZ9: 2 | JA9: 3 | JB9: 1 | JC9: 2 | JD9: 1 | JE9: 1 | JF9: 4 | JG9: 2 | JH9: 2 | JI9: 2 | JJ9: 1 | JK9: 2 | JL9: 4 | JM9: 3 | JN9: 3 | JO9: 1 | JP9: 2 | JQ9: 2 | JR9: 1 | JS9: 3 | JT9: 3 | JU9: 1 | JV9: 3 | JW9: 1 | JX9: 2 | JY9: 1 | JZ9: 3 | KA9: 1 | KB9: 2 | KC9: 1 | KD9: 2 | KE9: 2 | KF9: 1 | KG9: 1 | KH9: 1 | KI9: 2 | KJ9: 1 | KK9: 1 | KL9: 3 | KM9: 2 | KN9: 3 | KO9: 1 | KP9: 3 | KQ9: 3 | KR9: 1 | KS9: 2 | KT9: 3 | KU9: 1 | KV9: 4 | KW9: 2 | KX9: 2 | KY9: 3 | KZ9: 3 | LA9: 2 | LB9: 2 | LC9: 1 | LD9: 4 | LE9: 2 | LF9: 2 | LG9: 2 | LH9: 3 | LI9: 2 | LJ9: 1 | LK9: 1 | LL9: 2 | LM9: 2 | LN9: 3 | LO9: 2 | LP9: 4 | LQ9: 1 | LR9: 1 | LS9: 1 | LT9: 3 | LU9: 4 | LV9: 1 | LW9: 1 | LX9: 1 | LY9: 4 | LZ9: 2 | MA9: 2 | MB9: 2 | MC9: 2 | MD9: 4 | ME9: 2 | MF9: 3 | MG9: 1 | MH9: 2 | MI9: 1 | MJ9: 1 | MK9: 1 | ML9: 3 | MM9: 3 | MN9: 1 | MO9: 1 | MP9: 1 | MQ9: 1 | MR9: 2 | MS9: 3 | MT9: 2 | MU9: 3 | MV9: 4 | MW9: 1 | MX9: 1 | MY9: 1 | MZ9: 1 | NA9: 1 | NB9: 1 | NC9: 3 | ND9: 2 | NE9: 2 | NF9: 1 | NG9: 2 | NH9: 1 | NI9: 1 | NJ9: 3 | NK9: 3 | NL9: 2 | NM9: 2 | NN9: 2 | NO9: 3 | NP9: 1 | NQ9: 4 | NR9: 3 | NS9: 1 | NT9: 3 | NU9: 1 | NV9: 3 | NW9: 2 | NX9: 2 | NY9: 2 | NZ9: 4 | OA9: 1 | OB9: 1 | OC9: 1 | OD9: 2 | OE9: 2 | OF9: 1 | OG9: 1 | OH9: 2 | OI9: 5 | OJ9: 2 | OK9: 1 | OL9: 1 | OM9: 1 | ON9: 1 | OO9: 1 | OP9: 3 | OQ9: 3 | OR9: 2 | OS9: 1 | OT9: 2 | OU9: 1 | OV9: 1 | OW9: 2 | OX9: 1 | OY9: 2 | OZ9: 3 | PA9: 1 | PB9: 1 | PC9: 2 | PD9: 4 | PE9: 4 | PF9: 1 | PG9: 4 | PH9: 3 | PI9: 2 | PJ9: 2 | PK9: 2 | PL9: 2 | PM9: 4 | PN9: 3 | PO9: 2 | PP9: 1 | PQ9: 2 | PR9: 2 | PS9: 1 | PT9: 2 | PU9: 2 | PV9: 1 | PW9: 1 | PX9: 2 | PY9: 3 | PZ9: 2 | QA9: 1 | QB9: 2 | QC9: 1 | QD9: 3 | QE9: 1 | QF9: 3 | QG9: 3 | QH9: 2 | QI9: 1 | QJ9: 2 | QK9: 1 | QL9: 3 | QM9: 1 | QN9: 2 | QO9: 1 | QP9: 1 | QQ9: 2 | QR9: 1 | QS9: 3 | QT9: 1 | QU9: 1 | QV9: 1 | QW9: 2 | QX9: 2 | QY9: 2 | QZ9: 1000

Sheet Q3
A1: Row Labels | B1: Sum of Stay Duration (days)
A2: Diabetes | B2: 1341
A3: Flu | B3: 1450
A4: Fracture | B4: 1441
A5: Heart Disease | B5: 1291
A6: Hypertension | B6: 1222
A7: Migraine | B7: 1122
A8: Grand Total | B8: 7867

Sheet Q5.
A1: Row Labels | B1: Count of Admission Date
A2: 1 | B2: 62
A3: 2 | B3: 81
A4: 3 | B4: 69
A5: 4 | B5: 51
A6: 5 | B6: 60
A7: 6 | B7: 84
A8: 7 | B8: 69
A9: 8 | B9: 67
A10: 9 | B10: 67
A11: 10 | B11: 66
A12: 11 | B12: 81
A13: 12 | B13: 59
... A16: 15 | B16: 45
A17: Grand Total | B17: 1000

Sheet Q6
A1: Row Labels | B1: Count of Medication
A2: Cardiology | B2: 165
A3: Emergency | B3: 166
A4: General Medicine | B4: 181
A5: ICU | B5: 179
A6: Neurology | B6: 173
A7: Orthopedics | B7: 136
A8: Grand Total | B8: 1000

Sheet Q8
A1: Row Labels | B1: Count of Admission Date | C1: Count of Discharge Date
A2: Emergency | B2: 299 | C2: 299
A3: Routine | B3: 701 | C3: 701
A4: Grand Total | B4: 1000 | C4: 1000

Sheet Q9
A1: Row Labels | B1: Count of Patient ID | C1: Count of Doctor
A2: Cardiology | B2: 165 | C2: 165
A3: Emergency | B3: 166 | C3: 166
A4: General Medicine | B4: 181 | C4: 181
A5: ICU | B5: 179 | C5: 179
A6: Neurology | B6: 173 | C6: 173
A7: Orthopedics | B7: 136 | C7: 136
A8: Grand Total | B8: 1000 | C8: 1000
